Workbook

Sheet README
A1: GPU demand in financial services: sizing, cost, value and pricing model
A2: Companion to esthercs.dev/research/fs-gpu. Built 19 October 2026 by Esther Suebsubanant. All figures are dated and sourced on the Assumptions sheet.
A4: How to read this workbook
A5: Blue text | B5: Hardcoded input. Every one has a source or is labelled as my assumption on the Assumptions sheet.
A6: Black text | B6: Formula on the same sheet.
A7: Green text | B7: Formula that pulls a value from another sheet.
A8: Yellow fill | B8: Scenario lever you are expected to change.
A9: Formula column | B9: Each computed row states its formula in words, so you can audit without clicking into cells.
A11: Sheets
A12: Assumptions | B12: Every input, with unit, value, date read and source URL.
A13: TopDown | B13: Three independent top-down paths to the 2026 financial services accelerated-compute market, then a reconciliation.
A14: BottomUp | B14: Segment by segment: number of institutions, adoption, GPUs per adopter, price per installed GPU, refresh cycle. Gives installed base, annual spend and a 2030 view.
A15: Workloads | B15: Compute-demand sanity checks: how many GPUs an employee copilot, a fraud scorer and a quant research cluster actually need.
A16: TCO | B16: Five-year total cost of ownership of one 8-GPU Blackwell node on-premises versus renting the same GPUs in the cloud, with the breakeven utilisation.
A17: Configs | B17: Four reference configurations (regulated pod, bank SuperPOD class, sovereign NVL72 AI factory, quant research factory) evaluated on specification, five-year cost, unit economics, workload fit and value fit.
A18: Value | B18: What the compute buys: fraud prevented, cost taken out, risk-engine consolidation, productivity. Value-to-cost ratios per use case.
A19: Pricing | B19: Effective price per GPU-hour and per million tokens across buying routes, NVIDIA's gross margin, and where pricing power sits.
A20: Sources | B20: Numbered source list matching the article.
A22: Units | B22: Dollars are US dollars. Money in millions unless the header says otherwise. Percentages are stored as fractions. Years are calendar years unless marked FY (NVIDIA fiscal year ends late January).

Sheet Assumptions
A1: Assumptions and inputs
A2: Blue = hardcoded input. Change a value here and every sheet recalculates. 'My assumption' means no public figure exists and the number is my estimate, flagged so you can argue with it.
A4: Key | B4: Input | C4: Value | D4: Unit | E4: Read / dated | F4: Source
B5: Top-down market inputs
A6: it_bank | B6: Banking and investment services enterprise IT spending, 2026 | C6: 857.5 | D6: $B | E6: 4Q25 forecast | F6: Gartner, Forecast: Enterprise IT Spending for the Banking and Investment Services Market, Worldwide, 2023-2029, 4Q25. https://www.gartner.com/en/documents/7431362
A7: it_bank_g | B7: Growth of that spending in 2026 | C7: 0.095 | D7: fraction | E7: 4Q25 | F7: Same Gartner document (9.5%).
A8: it_world | B8: Worldwide IT spending, 2026 | C8: 6369 | D8: $B | E8: 27 Jul 2026 | F8: Gartner press release, 27 Jul 2026. https://www.gartner.com/en/newsroom/press-releases/2026-07-27-gartner-forecasts-worldwide-it-spending-to-grow-14-point-2-percent-in-2026-totaling-6-point-37-trillion
A9: dcs_world | B9: Worldwide data center systems spending, 2026 | C9: 822 | D9: $B | E9: 27 Jul 2026 | F9: Same Gartner release, Table 1 (2025: $506B; 2026 growth 62.5%).
A10: dcs_world_25 | B10: Worldwide data center systems spending, 2025 | C10: 506 | D10: $B | E10: 27 Jul 2026 | F10: Same Gartner release, Table 1.
A11: ai_infra_26 | B11: Worldwide AI infrastructure spending, 2026 (AI-optimised IaaS, AI servers, network fabric, AI semiconductors, devices) | C11: 1484.397 | D11: $B | E11: 16 Sep 2026 | F11: Gartner press release, 16 Sep 2026, Table 1. https://www.gartner.com/en/newsroom/press-releases/2026-09-16-gartner-forecasts-worldwide-ai-spending-to-grow-49-point-5-percent-in-2026
A12: ai_infra_25 | B12: Worldwide AI infrastructure spending, 2025 | C12: 981.92 | D12: $B | E12: 16 Sep 2026 | F12: Same Gartner release.
A13: ai_infra_27 | B13: Worldwide AI infrastructure spending, 2027 | C13: 1977.685 | D13: $B | E13: 16 Sep 2026 | F13: Same Gartner release.
A14: ai_total_26 | B14: Worldwide AI spending, all segments, 2026 | C14: 2670.46 | D14: $B | E14: 16 Sep 2026 | F14: Same Gartner release ($2.67T, +49.5%).
A15: ai_iaas_26 | B15: Worldwide AI-optimised IaaS spending, 2026 | C15: 42.276 | D15: $B | E15: 10 Aug 2026 | F15: Gartner press release, 10 Aug 2026. https://www.gartner.com/en/newsroom/press-releases/2026-08-10-gartner-forecasts-worldwide-artificial-intelligence-optimized-iaas-spending-to-grow-96-percent-in-2026
A16: ai_iaas_inf | B16: Share of AI-optimised IaaS spend that is inference, 2026 | C16: 0.55 | D16: fraction | E16: 10 Aug 2026 | F16: Same Gartner release ($23.3B inference, $19B training).
A17: idc_bank_24 | B17: Banking AI spending, 2024 (IDC) | C17: 31.3 | D17: $B | E17: 21 Aug 2024 | F17: IDC, Worldwide AI and Generative AI Spending Industry Outlook. https://www.idc.com/resource-center/blog/idcs-worldwide-ai-and-generative-ai-spending-industry-outlook/
... A29: nvda_q3_guide | B29: NVIDIA Q3 FY2027 revenue outlook | C29: 108 | D29: $B | E29: Aug 2026 | F29: Same release ($108.0B plus or minus 2%).
B30: Bottom-up: institution counts
A31: n_gsib | B31: Global systemically important banks | C31: 29 | D31: institutions | E31: 27 Nov 2025 | F31: FSB 2025 G-SIB list. https://www.fsb.org/2025/11/2025-list-of-global-systemically-important-banks-g-sibs/
A32: n_top100 | B32: Other banks in the world's 100 largest by assets (100 less 29 G-SIBs) | C32: 71 | D32: institutions | E32: 29 Apr 2026 | F32: S&P Global Market Intelligence, The world's largest banks by assets, 2026 (21 China, 12 US, 8 Japan). https://www.spglobal.com/market-intelligence/en/news-insights/research/2026/04/the-worlds-largest-banks-by-assets-2026
A33: n_regional | B33: Regional and mid-size banks with a credible AI programme (ranks 101 to 500 globally) | C33: 400 | D33: institutions | E33: My assumption | F33: S&P Capital IQ Pro covers 15,000 banks; FDIC alone has 4,238 insured institutions (2Q 2026). I take ranks 101-500 as the addressable tier for owned GPUs. https://www.fdic.gov/news/press-releases/2026/fdic-insured-institutions-reported-return-assets-137-percent-and-net
A34: n_payments | B34: Payment networks, processors and large fintechs (Visa, Mastercard, Amex, PayPal, Stripe, Adyen, Revolut, Nubank, etc.) | C34: 25 | D34: institutions | E34: My assumption | F34: Count of global networks, acquirers and fintechs with transaction foundation models in production or announced (GTC 2026 named Mastercard, Revolut, Adyen).
A35: n_quant | B35: Quant trading and market-making firms with owned GPU research clusters | C35: 40 | D35: institutions | E35: My assumption | F35: XTX (>25,000 GPUs), HRT (Blackwell AI factory), Jump (Vera Rubin), Jane Street, Citadel Securities, Two Sigma, DE Shaw, Qube, Millennium, Point72, DRW, SIG, Optiver, IMC, High-Flyer and peers. https://www.xtxmarkets.com/
A36: n_hedge | B36: Large hedge funds and asset managers (>$20B AUM) buying GPUs beyond the quant tier | C36: 150 | D36: institutions | E36: My assumption | F36: Order of magnitude from Preqin-style rankings; most rent rather than own.
A37: n_insurers | B37: Large insurers and reinsurers with owned AI infrastructure | C37: 60 | D37: institutions | E37: My assumption | F37: Allianz, AXA, Ping An, Munich Re, Swiss Re, Zurich, Chubb, AIG, Prudential, MetLife and peers. Underwriting, claims and catastrophe modelling.
A38: n_exchanges | B38: Exchanges, clearing houses and market data firms | C38: 15 | D38: institutions | E38: My assumption | F38: LSEG (GPU-accelerated analytics with NVIDIA, Oct 2026), ICE, CME, Nasdaq, DTCC, Bloomberg, S&P Global, MSCI. https://blogs.nvidia.com/feed/
B39: Bottom-up: adoption and GPU intensity, 2026
A40: adopt_large | B40: Share of large institutions (>1,000 staff) actively using AI | C40: 0.76 | D40: fraction | E40: Mar 2026 | F40: NVIDIA State of AI in FS 2026 as summarised by R. K. Thakur: 76% of firms over 1,000 employees. https://ninza7.medium.com/nvidias-ai-in-finance-report-just-confirmed-what-most-people-aren-t-ready-to-hear-2f26de01186d
A41: adopt_all | B41: Share of all financial firms actively using AI | C41: 0.65 | D41: fraction | E41: 22 Jan 2026 | F41: NVIDIA State of AI in FS 2026 (65%, up from 45%).
A42: own_share | B42: Of adopters, share that own or dedicate GPUs (rest rent via cloud only) | C42: 0.55 | D42: fraction | E42: My assumption | F42: NVIDIA 2026 survey: 47% hybrid. CSA/Anjuna 2026: hybrid and multi-cloud dominant. I set owned-or-dedicated at 55% for large institutions. Lever.
A43: gpu_gsib | B43: Installed GPUs per G-SIB adopter, 2026 | C43: 6000 | D43: GPUs | E43: My assumption | F43: BNY Mellon's 2024 SuperPOD was 'dozens' of DGX H100 (8 GPUs each), i.e. 300-500 GPUs for one bank's first system, with more coming; JPMorgan runs a $19.8B tech budget with 230,000 LLM Suite users. A G-SIB fleet across training, fraud, risk and inference of 3,000-10,000 GPUs is consistent with that; JPMorgan's ~$2B annual AI investment with 30% to infrastructure would alone buy ~12,000 GPUs a year. Fleet mean 6,000. Lever.
A44: gpu_top100 | B44: Installed GPUs per other top-100 bank adopter | C44: 1000 | D44: GPUs | E44: My assumption | F44: One to two SuperPOD-class systems or equivalent cloud-dedicated capacity.
A45: gpu_regional | B45: Installed GPUs per regional bank adopter | C45: 64 | D45: GPUs | E45: My assumption | F45: Four to eight nodes: an inference pod for document processing and a fraud model.
A46: gpu_payments | B46: Installed GPUs per payments adopter | C46: 2000 | D46: GPUs | E46: My assumption | F46: Transaction foundation models trained on hundreds of millions to 125B transactions (Mastercard) plus real-time scoring at up to 76,000 TPS (Visa).
A47: gpu_quant | B47: Installed GPUs per quant firm | C47: 4000 | D47: GPUs | E47: My assumption | F47: XTX discloses >25,000; High-Flyer 10,000 A100; HRT and Jump build AI factories; Jane Street, Citadel Securities and Two Sigma are large; the tail (DRW, SIG, Optiver, IMC, Qube, Millennium pods) runs 500-3,000. Fleet mean across 40 firms 4,000. Lever.
A48: gpu_hedge | B48: Installed or dedicated GPUs per large hedge fund / asset manager adopter | C48: 150 | D48: GPUs | E48: My assumption | F48: Mostly rented; dedicated reservations counted.
A49: gpu_insurer | B49: Installed GPUs per insurer adopter | C49: 200 | D49: GPUs | E49: My assumption | F49: Claims, underwriting and catastrophe modelling; Allianz Partners fraud detection 1.5x (WEF 2026).
A50: gpu_exchange | B50: Installed GPUs per exchange / market data adopter | C50: 400 | D50: GPUs | E50: My assumption | F50: LSEG, Bloomberg and S&P Global run market analytics and LLMs at scale.
A51: price_gpu_sys | B51: System-level price per installed GPU (server, networking, storage share), 2026 blend of Hopper and Blackwell | C51: 48000 | D51: $ per GPU | E51: Sep-Oct 2026 | F51: DGX B200 8-GPU $280k-$320k OEM anchor = $35k-$40k/GPU; HGX B200 $400k-$500k = $50k-$62k/GPU; GB200 NVL72 $2M-$3M = $28k-$42k/GPU; H100 server $250k-$320k = $31k-$40k/GPU. B200 chips alone are $45k-$50k on the street (Oct 2026). Blend $48k per installed GPU incl. server, networking and storage share, reflecting Hopper still in fleets. https://tech-insider.org/nvidia-blackwell-gpu-pricing/
... A54: rent_share_spend | B54: Cloud-rented GPU spend as a share of owned-GPU annual spend | C54: 0.6 | D54: fraction | E54: My assumption | F54: Gartner: AI-optimised IaaS is $42B against $822B data center systems worldwide (5%), but FS rents a larger share because regulation pushes workloads to dedicated cloud. Lever.
...

Sheet TopDown
A1: Top-down: three paths to the 2026 financial services accelerated-compute market
A2: Each path starts from a published market figure and applies stated shares. Column D spells out the formula. $B unless noted.
A4: Line | B4: Item | C4: Value | D4: Formula (in words) and source
B5: Path A: from the data center systems market (Gartner)
A6: A1 | B6: Banking and investment services IT spending, 2026 | C6: =Assumptions!$C$6 -> 857.5 | D6: Gartner 4Q25 forecast: $857.5B, up 9.5%.
A7: A2 | B7: Worldwide IT spending, 2026 | C7: =Assumptions!$C$8 -> 6369 | D7: Gartner Jul 2026: $6,369B.
A8: A3 | B8: Banking share of worldwide IT | C8: =C6/C7 -> 0.13463652 | D8: A1 / A2. Banks are about one dollar in seven of world IT.
A9: A4 | B9: Worldwide data center systems spending, 2026 | C9: =Assumptions!$C$9 -> 822 | D9: Gartner Jul 2026: $822B, up 62.5%.
A10: A5 | B10: Enterprise share of data center systems (excludes hyperscalers, neoclouds, AI labs) | C10: =Assumptions!$C$21 -> 0.28 | D10: Assumption 28%: hyperscaler capex alone is ~$700B in 2026.
A11: A6 | B11: Enterprise data center systems spend | C11: =C9*C10 -> 230.16 | D11: A4 x A5.
A12: A7 | B12: Financial services share of enterprise data center systems | C12: =Assumptions!$C$22 -> 0.17 | D12: Assumption 17%, above the 13.5% IT share because capital markets and payments are compute-heavy.
A13: A8 | B13: Financial services data center systems spend | C13: =C11*C12 -> 39.1272 | D13: A6 x A7.
A14: A9 | B14: Share of data center systems that is accelerated compute | C14: =Assumptions!$C$24 -> 0.62 | D14: Assumption 62%. See Assumptions for derivation from Gartner growth.
A15: A10 | B15: Financial services accelerated-compute systems, 2026 (Path A) | C15: =C13*C14 -> 24.258864 | D15: A8 x A9. Owned servers and racks, not cloud rental and not chips alone.
A16: A11 | B16: NVIDIA share of accelerators | C16: =Assumptions!$C$25 -> 0.8 | D16: Assumption 80% (IDC 81%, Silicon Analysts ~75%).
A17: A12 | B17: NVIDIA-addressable FS accelerated systems, 2026 (Path A) | C17: =C15*C16 -> 19.407091 | D17: A10 x A11.
B18: Path B: from the AI cloud market (Gartner AI-optimised IaaS)
A19: B1 | B19: Worldwide AI-optimised IaaS spending, 2026 | C19: =Assumptions!$C$15 -> 42.276 | D19: Gartner Aug 2026: $42.3B, up 96%. The GPU-rental market.
A20: B2 | B20: Financial services share of AI cloud spend | C20: =Assumptions!$C$19 -> 0.133 | D20: IDC: banking was 13.3% of global AI spend in 2024 and the #2 industry. Applied to AI IaaS.
A21: B3 | B21: Financial services AI cloud rental, 2026 | C21: =C19*C20 -> 5.622708 | D21: B1 x B2.
A22: B4 | B22: Rented share of owned spend (lever) | C22: =Assumptions!$C$54 -> 0.6 | D22: Assumption 60%: for every $1 FS spends on owned GPU systems it rents $0.60 in the cloud.
A23: B5 | B23: Implied owned GPU systems | C23: =C21/C22 -> 9.37118 | D23: B3 / B4.
A24: B6 | B24: Financial services GPU compute, owned plus rented, 2026 (Path B) | C24: =C21+C23 -> 14.993888 | D24: B3 + B5.
A25: B7 | B25: Context: worldwide AI infrastructure incl. devices and hyperscalers (Gartner) | C25: =Assumptions!$C$11 -> 1484.397 | D25: Gartner Sep 2026: $1,484B. Not used in the path because it includes AI PCs, phones and hyperscaler buildout.
B26: Path C: from the banking AI budget (IDC, grown forward)
A27: C1 | B27: Banking AI spending, 2024 | C27: =Assumptions!$C$17 -> 31.3 | D27: IDC Aug 2024: $31.3B.
A28: C2 | B28: CAGR applied | C28: =Assumptions!$C$18 -> 0.3 | D28: IDC Americas five-year CAGR 30%.
A29: C3 | B29: Banking AI spending, 2026 | C29: =C27*(1+C28)^2 -> 52.897 | D29: C1 x (1 + C2)^2. Two years of growth.
A30: C4 | B30: Uplift for non-bank financial services (insurance, capital markets, payments) over banking | C30: 0.45 | D30: Assumption: IDC's banking line excludes insurers, exchanges, asset managers and the quant firms, which carry the largest GPU fleets. +45%.
A31: C5 | B31: Financial services AI spending, 2026 | C31: =C29*(1+C30) -> 76.70065 | D31: C3 x (1 + C4).
A32: C6 | B32: Share of AI budget spent on infrastructure | C32: =Assumptions!$C$23 -> 0.3 | D32: NVIDIA 2026 survey: 30% of new investment to AI infrastructure.
A33: C7 | B33: Financial services AI infrastructure, 2026 (Path C) | C33: =C31*C32 -> 23.010195 | D33: C5 x C6.
B34: Reconciliation
A35: R1 | B35: Path A: accelerated systems from the IT budget | C35: =C15 -> 24.258864
A36: R2 | B36: Path B: GPU compute from the AI cloud market | C36: =C24 -> 14.993888
A37: R3 | B37: Path C: AI infrastructure from the AI budget | C37: =C33 -> 23.010195
A38: R4 | B38: Average of the three paths | C38: =AVERAGE(C35,C36,C37) -> 20.754316 | D38: AVERAGE(R1:R3). Path A is owned systems only; B and C include cloud. The spread is informative, not an error.
A39: R5 | B39: Spread (max minus min) as share of average | C39: =(MAX(C35,C36,C37)-MIN(C35,C36,C37))/C38 -> 0.44641202 | D39: (MAX - MIN) / R4.
A40: R6 | B40: Bottom-up total for comparison (owned plus rented, 2026) | C40: =BottomUp!C32 -> 11.880614 | D40: Pulled from BottomUp sheet, line 'Total FS GPU spend 2026 incl. rented'.
A41: R7 | B41: Bottom-up as share of top-down average | C41: =C40/C38 -> 0.57244067 | D41: R6 / R4. Below 100% means the segment build does not reach what the budget view implies.
...

Sheet BottomUp
A1: Bottom-up: GPUs installed and bought by financial services segment, 2026 and 2030
A2: Installed base = institutions x adoption x owned share x GPUs per adopter. Annual spend = installed base / refresh years x price per GPU, plus growth capex. $M unless noted.
A4: Segment | B4: Institutions | C4: AI adoption | D4: Own or dedicate GPUs | E4: Adopters owning GPUs | F4: GPUs per adopter | G4: Installed GPUs 2026 | H4: Price per installed GPU ($) | I4: Installed value ($M) | J4: Replacement spend 2026 ($M) | K4: Growth spend 2026 ($M) | L4: Total owned spend 2026 ($M)
A5: G-SIBs | B5: =Assumptions!$C$31 -> 29 | C5: =Assumptions!$C$40 -> 0.76 | D5: =Assumptions!$C$42 -> 0.55 | E5: =B5*C5*D5 -> 12.122 | F5: =Assumptions!$C$43 -> 6000 | G5: =E5*F5 -> 72732 | H5: =Assumptions!$C$51 -> 48000 | I5: =G5*H5/1000000 -> 3491.136 | J5: =I5/Assumptions!$C$52 -> 698.2272 | K5: =I5*Assumptions!$C$53 -> 1047.3408 | L5: =J5+K5 -> 1745.568
A6: Other top-100 banks | B6: =Assumptions!$C$32 -> 71 | C6: =Assumptions!$C$40 -> 0.76 | D6: =Assumptions!$C$42 -> 0.55 | E6: =B6*C6*D6 -> 29.678 | F6: =Assumptions!$C$44 -> 1000 | G6: =E6*F6 -> 29678 | H6: =Assumptions!$C$51 -> 48000 | I6: =G6*H6/1000000 -> 1424.544 | J6: =I6/Assumptions!$C$52 -> 284.9088 | K6: =I6*Assumptions!$C$53 -> 427.3632 | L6: =J6+K6 -> 712.272
A7: Regional and mid-size banks (ranks 101-500) | B7: =Assumptions!$C$33 -> 400 | C7: =Assumptions!$C$41 -> 0.65 | D7: =Assumptions!$C$42 -> 0.55 | E7: =B7*C7*D7 -> 143 | F7: =Assumptions!$C$45 -> 64 | G7: =E7*F7 -> 9152 | H7: =Assumptions!$C$51 -> 48000 | I7: =G7*H7/1000000 -> 439.296 | J7: =I7/Assumptions!$C$52 -> 87.8592 | K7: =I7*Assumptions!$C$53 -> 131.7888 | L7: =J7+K7 -> 219.648
A8: Payment networks, processors, large fintechs | B8: =Assumptions!$C$34 -> 25 | C8: =Assumptions!$C$40 -> 0.76 | D8: =Assumptions!$C$42 -> 0.55 | E8: =B8*C8*D8 -> 10.45 | F8: =Assumptions!$C$46 -> 2000 | G8: =E8*F8 -> 20900 | H8: =Assumptions!$C$51 -> 48000 | I8: =G8*H8/1000000 -> 1003.2 | J8: =I8/Assumptions!$C$52 -> 200.64 | K8: =I8*Assumptions!$C$53 -> 300.96 | L8: =J8+K8 -> 501.6
A9: Quant trading and market-making firms | B9: =Assumptions!$C$35 -> 40 | C9: 1 | D9: 1 | E9: =B9*C9*D9 -> 40 | F9: =Assumptions!$C$47 -> 4000 | G9: =E9*F9 -> 160000 | H9: =Assumptions!$C$51 -> 48000 | I9: =G9*H9/1000000 -> 7680 | J9: =I9/Assumptions!$C$52 -> 1536 | K9: =I9*Assumptions!$C$53 -> 2304 | L9: =J9+K9 -> 3840
A10: Large hedge funds and asset managers | B10: =Assumptions!$C$36 -> 150 | C10: =Assumptions!$C$40 -> 0.76 | D10: =Assumptions!$C$42 -> 0.55 | E10: =B10*C10*D10 -> 62.7 | F10: =Assumptions!$C$48 -> 150 | G10: =E10*F10 -> 9405 | H10: =Assumptions!$C$51 -> 48000 | I10: =G10*H10/1000000 -> 451.44 | J10: =I10/Assumptions!$C$52 -> 90.288 | K10: =I10*Assumptions!$C$53 -> 135.432 | L10: =J10+K10 -> 225.72
A11: Large insurers and reinsurers | B11: =Assumptions!$C$37 -> 60 | C11: =Assumptions!$C$40 -> 0.76 | D11: =Assumptions!$C$42 -> 0.55 | E11: =B11*C11*D11 -> 25.08 | F11: =Assumptions!$C$49 -> 200 | G11: =E11*F11 -> 5016 | H11: =Assumptions!$C$51 -> 48000 | I11: =G11*H11/1000000 -> 240.768 | J11: =I11/Assumptions!$C$52 -> 48.1536 | K11: =I11*Assumptions!$C$53 -> 72.2304 | L11: =J11+K11 -> 120.384
A12: Exchanges, clearing, market data | B12: =Assumptions!$C$38 -> 15 | C12: =Assumptions!$C$40 -> 0.76 | D12: =Assumptions!$C$42 -> 0.55 | E12: =B12*C12*D12 -> 6.27 | F12: =Assumptions!$C$50 -> 400 | G12: =E12*F12 -> 2508 | H12: =Assumptions!$C$51 -> 48000 | I12: =G12*H12/1000000 -> 120.384 | J12: =I12/Assumptions!$C$52 -> 24.0768 | K12: =I12*Assumptions!$C$53 -> 36.1152 | L12: =J12+K12 -> 60.192
A13: Total | B13: =SUM(B5:B12) -> 790 | E13: =SUM(E5:E12) -> 329.3 | G13: =SUM(G5:G12) -> 309391 | I13: =SUM(I5:I12) -> 14850.768 | J13: =SUM(J5:J12) -> 2970.1536 | K13: =SUM(K5:K12) -> 4455.2304 | L13: =SUM(L5:L12) -> 7425.384
A15: Formulas
A16: Adopters owning GPUs | B16: Institutions x AI adoption x Own-or-dedicate share
A17: Installed GPUs 2026 | B17: Adopters owning GPUs x GPUs per adopter
A18: Installed value ($M) | B18: Installed GPUs x Price per installed GPU / 1,000,000
A19: Replacement spend 2026 | B19: Installed value / Refresh cycle (years). Steady-state refresh of the fleet.
A20: Growth spend 2026 | B20: Installed value x Fleet growth rate. New capacity added this year.
A21: Total owned spend 2026 | B21: Replacement + Growth
A27: Summary 2026
A28: Installed GPUs, financial services, 2026 | C28: =G13 -> 309391 | D28: Sum of column G.
A29: Installed value ($M) | C29: =I13 -> 14850.768
A30: Owned GPU spend 2026 ($M) | C30: =L13 -> 7425.384
A31: Cloud-rented GPU spend 2026 ($M) | C31: =C30*Assumptions!$C$54 -> 4455.2304 | D31: Owned spend x rented-share lever (60%).
A32: Total FS GPU spend 2026 incl. rented ($B) | C32: =(C30+C31)/1000 -> 11.880614 | D32: (Owned + Rented) / 1000. Feeds TopDown reconciliation R6.
A33: NVIDIA share of that spend ($B) | C33: =C32*Assumptions!$C$25 -> 9.5044915
A34: Quant and payments share of installed GPUs | C34: =(G8+G9)/G13 -> 0.58469703 | D34: (payments GPUs + quant GPUs) / total. Shows how concentrated the fleet is outside the banks.
A36: Projection 2026 to 2030
A37: Year | B37: Installed GPUs | C37: Installed value ($M) | D37: Replacement ($M) | E37: Growth ($M) | F37: Owned spend ($M)
A38: 2026 | B38: =C28 -> 309391 | C38: =B38*Assumptions!$C$51/1000000 -> 14850.768 | D38: =C38/Assumptions!$C$52 -> 2970.1536 | E38: =C38*Assumptions!$C$53 -> 4455.2304 | F38: =D38+E38 -> 7425.384
A39: 2027 | B39: =B38*(1+Assumptions!$C$53) -> 402208.3 | C39: =B39*Assumptions!$C$51/1000000 -> 19305.998 | D39: =C39/Assumptions!$C$52 -> 3861.1997 | E39: =C39*Assumptions!$C$53 -> 5791.7995 | F39: =D39+E39 -> 9652.9992
A40: 2028 | B40: =B39*(1+Assumptions!$C$53) -> 522870.79 | C40: =B40*Assumptions!$C$51/1000000 -> 25097.798 | D40: =C40/Assumptions!$C$52 -> 5019.5596 | E40: =C40*Assumptions!$C$53 -> 7529.3394 | F40: =D40+E40 -> 12548.899
A41: 2029 | B41: =B40*(1+Assumptions!$C$53) -> 679732.03 | C41: =B41*Assumptions!$C$51/1000000 -> 32627.137 | D41: =C41/Assumptions!$C$52 -> 6525.4275 | E41: =C41*Assumptions!$C$53 -> 9788.1412 | F41: =D41+E41 -> 16313.569
A42: 2030 | B42: =B41*(1+Assumptions!$C$53) -> 883651.64 | C42: =B42*Assumptions!$C$51/1000000 -> 42415.278 | D42: =C42/Assumptions!$C$52 -> 8483.0557 | E42: =C42*Assumptions!$C$53 -> 12724.584 | F42: =D42+E42 -> 21207.639
A43: Formulas: GPUs(t) = GPUs(t-1) x (1 + fleet growth). Value = GPUs x price per GPU. Replacement = value / refresh years. Growth = value x growth rate. Price per GPU held flat: Blackwell to Rubin raises price per GPU but tokens per dollar fall faster, so dollars per installed GPU is roughly stable.

Sheet Workloads
A1: Workload sanity checks: how many GPUs does each use case actually need?
A2: Three builds from first principles. The point is the ratio between them: inference for staff and payments is small; research and training are where the fleets live.
A4: Line | B4: Item | C4: Value | D4: Formula (in words)
B5: 1. Employee assistant at a G-SIB (JPMorgan LLM Suite scale)
A6: W1 | B6: Enrolled users | C6: =Assumptions!$C$56 -> 230000 | D6: 230,000 (Forbes, Jul 2026).
A7: W2 | B7: Daily active share | C7: =Assumptions!$C$58 -> 0.5 | D7: Assumption 50%.
A8: W3 | B8: Tokens per active user per day | C8: =Assumptions!$C$57 -> 60000 | D8: 60,000 (iternal.ai ranges).
A9: W4 | B9: Tokens per day | C9: =C6*C7*C8 -> 6900000000 | D9: W1 x W2 x W3.
A10: W5 | B10: Average tokens per second over a 10-hour working day | C10: =C9/(10*3600) -> 191666.67 | D10: W4 / (10 x 3,600).
A11: W6 | B11: Peak tokens per second | C11: =C10*Assumptions!$C$59 -> 575000 | D11: W5 x peak factor (3x).
A12: W7 | B12: Tokens per second one Blackwell GPU serves (70B-class model) | C12: =Assumptions!$C$60 -> 2500 | D12: 2,500 tokens/s, conservative reading of NVIDIA's $0.02 per million tokens claim.
A13: W8 | B13: GPUs needed at peak, at target utilisation | C13: =C11/C12/Assumptions!$C$61 -> 383.33333 | D13: W6 / W7 / utilisation (60%).
A14: W9 | B14: Share of the assumed G-SIB fleet | C14: =C13/Assumptions!$C$43 -> 0.063888889 | D14: W8 / GPUs per G-SIB adopter (6,000). A bank-wide assistant for 230,000 people fits in a few hundred GPUs. Inference for staff is not what fills the fleet.
A15: W10 | B15: Annual tokens (250 working days), billions | C15: =C9*250/1000000000 -> 1725 | D15: W4 x 250 / 1e9.
A16: W11 | B16: Annual inference cost at NVIDIA's Blackwell $/M tokens ($M) | C16: =C15*1000*Assumptions!$C$122/1000000 -> 0.0345 | D16: W10 (billions) x 1,000 x $ per million tokens / 1e6. Marginal compute cost of serving the bank at $0.02/M tokens.
A17: W12 | B17: Same tokens at frontier API list price ($M) | C17: =C15*1000*Assumptions!$C$124/1000000 -> 10.35 | D17: W10 x 1,000 x API price / 1e6. The gap between W11 and W12 is the prize for banks that own inference on open models.
B18: 2. Real-time fraud scoring at a payment network (Visa scale)
A19: F1 | B19: Transactions per year | C19: =Assumptions!$C$62 -> 269000000000 | D19: 269 billion (Visa).
A20: F2 | B20: Average transactions per second | C20: =C19/Assumptions!$C$87/3600 -> 8529.934 | D20: F1 / 8,760 / 3,600.
A21: F3 | B21: Peak capacity transactions per second | C21: =Assumptions!$C$63 -> 76000 | D21: 76,000 TPS (Bloomberg).
A22: F4 | B22: FLOPs per scored transaction | C22: =Assumptions!$C$64 -> 2000000000 | D22: 2 GFLOPs (1B-parameter model forward pass). Assumption.
A23: F5 | B23: Peak compute needed, PFLOPS | C23: =C21*C22/1000000000000000 -> 0.152 | D23: F3 x F4 / 1e15.
A24: F6 | B24: Effective PFLOPS per GPU | C24: =Assumptions!$C$66 -> 2 | D24: 2 PFLOPS effective FP8 per Blackwell GPU.
A25: F7 | B25: GPUs of raw compute to score every transaction at peak, with 2x redundancy | C25: =2*C23/C24 -> 0.152 | D25: 2 x F5 / F6. Scoring an entire global card network at peak needs less than one GPU of FLOPs. The real count is set by latency budgets, regions and redundancy, so a network runs dozens of inference GPUs, not thousands.
A26: F8 | B26: Training a transaction foundation model: tokens seen (transactions x 50 tokens each) | C26: =Assumptions!$C$103*50 -> 6250000000000 | D26: Mastercard 125B transactions x ~50 tokens per transaction record.
A27: F9 | B27: Training FLOPs for the foundation model (6 x params x tokens) | C27: =6*Assumptions!$C$65*C26 -> 3.75e+23 | D27: Standard 6ND estimate: 6 x parameters (10B) x tokens.
A28: F10 | B28: GPU-hours at effective 2 PFLOPS | C28: =C27/(C24*1000000000000000)/3600 -> 52083.333 | D28: F9 / (F6 x 1e15) / 3,600.
A29: F11 | B29: GPUs to train in 30 days | C29: =C28/(30*24) -> 72.337963 | D29: F10 / 720 hours. One training run of a 10B transaction model on a year of data takes this many GPUs for a month; retraining monthly across several models and regions, plus research, is what justifies a 1,000-3,000 GPU payments fleet.
B30: 3. Quant research cluster (XTX scale)
A31: Q1 | B31: XTX Markets research GPUs | C31: =Assumptions!$C$67 -> 25000 | D31: Over 25,000 (XTX homepage).
A32: Q2 | B32: Ratio to the G-SIB employee assistant need (W8) | C32: =C31/C13 -> 65.217391 | D32: Q1 / W8. One trading firm runs two orders of magnitude more GPUs than a 230,000-person bank's assistant needs.
A33: Q3 | B33: Implied replacement value at $42k per installed GPU ($M) | C33: =C31*Assumptions!$C$51/1000000 -> 1200 | D33: Q1 x price per installed GPU / 1e6. XTX's actual fleet is older A100/V100, bought cheaper; this is what refreshing it costs.
A34: Q4 | B34: XTX disclosed data center capex, Finland ($M) | C34: =Assumptions!$C$68*1000 -> 1000 | D34: More than EUR 1B (Bloomberg) for five data centers, buildings and power, not GPUs.
A35: Q5 | B35: HRT research iteration speedup Blackwell vs Hopper | C35: =Assumptions!$C$69 -> 1.6 | D35: 1.6x (NVIDIA GTC 2026). A quant firm's buying trigger is research velocity, not tokens.
B36: Takeaway
B37: GPUs for the three builds: assistant (W8), fraud scoring (F7), one quant firm (Q1) | C37: =TEXT(C13,"#,##0")&" / "&TEXT(C25,"0.00")&" / "&TEXT(C31,"#,##0") -> 383 / 0.15 / 25,000 | D37: Text of W8 / F7 / Q1. Fleets in finance are driven by research and training, and inference count is set by latency, residency and redundancy rather than FLOPs.

Sheet TCO
A1: Five-year TCO: one 8-GPU Blackwell node on-premises vs the same GPUs rented in the cloud
A2: On-prem cost is largely fixed; cloud cost scales with hours used. The breakeven utilisation tells a bank when owning pays.
A4: Line | B4: Item | C4: Value | D4: Formula (in words)
B5: On-premises, one DGX B200 class node (8 GPUs), five years, $
A6: T1 | B6: System price | C6: =Assumptions!$C$72 -> 420000 | D6: $420,000, see Assumptions.
A7: T2 | B7: Networking, storage, installation | C7: =C6*Assumptions!$C$73 -> 105000 | D7: T1 x 25%.
A8: T3 | B8: Capital cost | C8: =C6+C7 -> 525000 | D8: T1 + T2.
A9: T4 | B9: Average IT power draw, kW | C9: =Assumptions!$C$74*Assumptions!$C$75 -> 10.725 | D9: 14.3 kW max x 75% average load.
A10: T5 | B10: Facility power incl. cooling, kW | C10: =C9*Assumptions!$C$76 -> 13.9425 | D10: T4 x PUE (1.3).
A11: T6 | B11: Electricity per year | C11: =C10*Assumptions!$C$87*Assumptions!$C$77 -> 11932.717 | D11: T5 x 8,760 hours x $/kWh (9.77c industrial, EIA Jul 2026).
A12: T7 | B12: Colocation per year (billed on max IT kW) | C12: =Assumptions!$C$74*Assumptions!$C$78*12 -> 35006.4 | D12: Max kW (14.3) x $204 per kW per month x 12. Colo contracts bill on committed power, not average draw.
A13: T8 | B13: Software and support per year | C13: =8*Assumptions!$C$79 -> 36000 | D13: 8 GPUs x $4,500 per GPU per year (AI Enterprise).
A14: T9 | B14: Operations staff per year | C14: =Assumptions!$C$80 -> 15000 | D14: $15,000 allocated per node.
A15: T10 | B15: Operating cost per year | C15: =C11+C12+C13+C14 -> 97939.117 | D15: T6 + T7 + T8 + T9.
A16: T11 | B16: Residual value recovered at end of year 5 | C16: =C6*Assumptions!$C$88 -> 42000 | D16: T1 x 10%.
A17: T12 | B17: Five-year TCO, on-premises | C17: =C8+C15*Assumptions!$C$81-C16 -> 972695.58 | D17: T3 + T10 x 5 - T11.
A18: T13 | B18: Share of five-year TCO that is the hardware | C18: =C8/C17 -> 0.53973721 | D18: T3 / T12.
A19: T14 | B19: Share that is power and facility | C19: =(C11+C12)*Assumptions!$C$81/C17 -> 0.24128369 | D19: (T6 + T7) x 5 / T12.
A20: T15 | B20: GPU-hours available over five years | C20: =8*Assumptions!$C$87*Assumptions!$C$81 -> 350400 | D20: 8 x 8,760 x 5.
A21: T16 | B21: GPU-hours actually used at owned utilisation | C21: =C20*Assumptions!$C$86 -> 227760 | D21: T15 x 65%.
A22: T17 | B22: Effective cost per used GPU-hour, on-premises | C22: =C17/C21 -> 4.2707042 | D22: T12 / T16. Compare with cloud prices below.
A23: T18 | B23: Effective cost per available GPU-hour (100% utilisation) | C23: =C17/C20 -> 2.7759577 | D23: T12 / T15. The floor an owner can reach.
B24: Cloud, same used GPU-hours, five years, $
A25: U1 | B25: Cloud cost at on-demand B200 price | C25: =C21*Assumptions!$C$82 -> 1592042.4 | D25: T16 x $6.99 per GPU-hour.
A26: U2 | B26: Cloud cost at reserved B200 price | C26: =C21*Assumptions!$C$83 -> 1081860 | D26: T16 x $4.75 per GPU-hour.
A27: U3 | B27: On-prem saving vs on-demand cloud | C27: =C25-C17 -> 619346.82 | D27: U1 - T12.
A28: U4 | B28: On-prem saving vs reserved cloud | C28: =C26-C17 -> 109164.42 | D28: U2 - T12. Negative means renting is cheaper at this utilisation.
A29: U5 | B29: On-prem TCO as share of on-demand cloud | C29: =C17/C25 -> 0.61097342 | D29: T12 / U1.
A30: U6 | B30: Breakeven utilisation vs on-demand cloud | C30: =C17/(C20*Assumptions!$C$82) -> 0.39713272 | D30: T12 / (T15 x on-demand price). Above this share of hours busy, owning is cheaper than renting on demand.
A31: U7 | B31: Breakeven utilisation vs reserved cloud | C31: =C17/(C20*Assumptions!$C$83) -> 0.58441215 | D31: T12 / (T15 x reserved price).
A32: U8 | B32: Same five-year used hours on H100 at the one-year rental price | C32: =C21*Assumptions!$C$85 -> 535236 | D32: T16 x $2.35. Note a B200 delivers several times the tokens of an H100 per hour, so this is not like for like; it shows why older-generation rental undercuts new-generation purchase for light workloads.
B33: Sensitivity: on-prem effective $/GPU-hour at different utilisation
B34: Utilisation 30% | C34: =C17/(C20*0.3) -> 9.2531924 | D34: T12 / (T15 x utilisation).
B35: Utilisation 45% | C35: =C17/(C20*0.45) -> 6.1687949 | D35: T12 / (T15 x utilisation).
B36: Utilisation 60% | C36: =C17/(C20*0.6) -> 4.6265962 | D36: T12 / (T15 x utilisation).
B37: Utilisation 75% | C37: =C17/(C20*0.75) -> 3.701277 | D37: T12 / (T15 x utilisation).
B38: Utilisation 90% | C38: =C17/(C20*0.9) -> 3.0843975 | D38: T12 / (T15 x utilisation).
B39: Scale: a 64-node SuperPOD-class system (512 GPUs)
A40: S1 | B40: Capital cost, 64 nodes | C40: =64*C8 -> 33600000 | D40: 64 x T3.
A41: S2 | B41: Facility power, kW | C41: =64*C10 -> 892.32 | D41: 64 x T5.
...

Sheet Value
A1: Value: what the compute buys, use case by use case
A2: Each block states the value evidence, the compute it plausibly runs on (from TCO and Workloads), and the ratio. Ratios above 10x mean compute price is not the constraint.
A4: Line | B4: Item | C4: Value | D4: Formula (in words)
B5: A. Fraud prevention at a payment network (Visa)
A6: VA1 | B6: Fraud prevented per year ($B) | C6: =Assumptions!$C$100 -> 28 | D6: $28B (Bloomberg, 2024).
A7: VA2 | B7: AI and data infrastructure spend per year ($B) | C7: =Assumptions!$C$101/10 -> 0.3 | D7: $3B over ten years / 10.
A8: VA3 | B8: Value to spend ratio | C8: =C6/C7 -> 93.333333 | D8: VA1 / VA2. Every dollar of AI and data infrastructure protected roughly this many dollars.
A9: VA4 | B9: Fraud prevented per transaction ($) | C9: =C6*1000000000/Assumptions!$C$62 -> 0.10408922 | D9: VA1 x 1e9 / transactions per year.
A10: VA5 | B10: GPUs needed to score at peak (from Workloads F7) | C10: =Workloads!C25 -> 0.152 | D10: Pulled from Workloads F7.
A11: VA6 | B11: Five-year TCO of a 2,000-GPU payments fleet ($M) | C11: =Assumptions!$C$46/8*TCO!C17/1000000 -> 243.1739 | D11: GPUs per payments adopter / 8 per node x node five-year TCO / 1e6. The fleet the bottom-up model assumes for a payments adopter.
A12: VA7 | B12: Annualised fleet cost as share of fraud prevented | C12: =(C11/5)/(C6*1000) -> 0.0017369564 | D12: (VA6 / 5) / (VA1 x 1,000). Compute is a rounding error against the fraud it stops.
A13: VA8 | B13: Incremental: 20% precision gain (Revolut) applied to the average organisation's $60M fraud loss ($M) | C13: =Assumptions!$C$105*Assumptions!$C$107 -> 12 | D13: $60M x 20%. What a transaction foundation model is worth to one mid-size issuer or acquirer per year, before false-positive savings.
A14: VA9 | B14: Five-year TCO of a 64-GPU regional-bank pod ($M) | C14: =8*TCO!C17/1000000 -> 7.7815647 | D14: 8 nodes x node TCO / 1e6. Matches the regional bank fleet assumption.
A15: VA10 | B15: Payback of that pod on VA8 alone (years) | C15: =C14/C13 -> 0.64846372 | D15: VA9 / VA8.
B16: B. Enterprise productivity at a G-SIB (JPMorgan)
A17: VB1 | B17: Reported AI savings per year ($B) | C17: =Assumptions!$C$108 -> 2 | D17: $2B (Forbes, Jul 2026).
A18: VB2 | B18: Reported AI investment per year ($B) | C18: =Assumptions!$C$109 -> 2 | D18: $2B (Olakai citing JPMorgan).
A19: VB3 | B19: Savings to investment ratio | C19: =C17/C18 -> 1 | D19: VB1 / VB2. Roughly break-even on the bank's own numbers, which is why budgets keep rising rather than exploding.
A20: VB4 | B20: Theoretical productivity value: users x loaded cost x time share x efficiency gain ($B) | C20: =Assumptions!$C$56*Assumptions!$C$112*Assumptions!$C$113*Assumptions!$C$111/1000000000 -> 3.01875 | D20: 230,000 x $150,000 x 25% x 35% / 1e9. The upper bound if self-reported gains convert to cost.
A21: VB5 | B21: Realised share of the theoretical value | C21: =C17/C20 -> 0.66252588 | D21: VB1 / VB4.
A22: VB6 | B22: Five-year TCO of the GPUs the assistant needs (Workloads W8) ($M) | C22: =Workloads!C13/8*TCO!C17/1000000 -> 46.60833 | D22: W8 GPUs / 8 x node TCO / 1e6.
A23: VB7 | B23: Annualised assistant compute as share of reported savings | C23: =(C22/5)/(C17*1000) -> 0.004660833 | D23: (VB6 / 5) / (VB1 x 1,000). The GPU bill for the assistant is small; integration, data and change cost dominate the $2B investment.
A24: VB8 | B24: Technology budget ($B) | C24: =Assumptions!$C$110 -> 19.8 | D24: $19.8B (JPMorganChase).
A25: VB9 | B25: AI investment as share of technology budget | C25: =C18/C24 -> 0.1010101 | D25: VB2 / VB8.
B26: C. Risk engine consolidation at a dealer bank (Murex XVA on GPU)
A27: VC1 | B27: CPU servers in the XVA grid | C27: =Assumptions!$C$118 -> 5000 | D27: 5,000 (assumption).
A28: VC2 | B28: Performance gain per GPU server vs CPU server | C28: =Assumptions!$C$114 -> 7 | D28: 7x (NVIDIA partners page, Murex).
A29: VC3 | B29: GPU nodes to replace the grid at equal throughput | C29: =C27/(C28*8) -> 89.285714 | D29: VC1 / (VC2 x 8 GPUs per node). Assumes one GPU ~ one CPU server x 7.
A30: VC4 | B30: CPU grid power, kW | C30: =C27*Assumptions!$C$117 -> 5000 | D30: VC1 x 1 kW.
A31: VC5 | B31: GPU replacement power, kW | C31: =C29*Assumptions!$C$74*Assumptions!$C$75 -> 957.58929 | D31: VC3 x 14.3 kW x 75%.
A32: VC6 | B32: Power reduction | C32: =1-C31/C30 -> 0.80848214 | D32: 1 - VC5 / VC4. Murex quotes 4x less energy; this build lands in the same region.
A33: VC7 | B33: Annual power and colo saving ($M) | C33: =((C30-C31)*Assumptions!$C$76*Assumptions!$C$87*Assumptions!$C$77+(C30-C31)*Assumptions!$C$78*12)/1000000 -> 14.393438 | D33: ((kW saved x PUE x 8,760 x $/kWh) + (kW saved x colo $/kW/mo x 12)) / 1e6.
A34: VC8 | B34: CPU grid refresh avoided, five-year ($M) | C34: =C27*Assumptions!$C$116/1000000 -> 125 | D34: VC1 x $25,000 / 1e6.
A35: VC9 | B35: GPU capital required ($M) | C35: =C29*TCO!C8/1000000 -> 46.875 | D35: VC3 x node capital cost / 1e6.
A36: VC10 | B36: Five-year net saving before the value of intraday risk ($M) | C36: =C34+C33*5-C35 -> 150.09219 | D36: VC8 + VC7 x 5 - VC9. Riskfuel's 'once a day to on demand' is the real prize and is not priced here.
B37: D. Quant research (XTX, HRT)
A38: VD1 | B38: Citadel Securities net trading revenue 2025 ($B) | C38: 12.2 | D38: quantvero 2026 summary; HRT ~$12.3B. Secondary source, order of magnitude only. https://www.quantvero.com/algo-trading/best-quant-trading-firms/
A39: VD2 | B39: Annualised cost of a 25,000-GPU research fleet at on-prem effective $/GPU-hour ($B) | C39: =25000*Assumptions!$C$87*Assumptions!$C$86*TCO!C22/1000000000 -> 0.60793474 | D39: 25,000 x 8,760 x 65% x effective $/GPU-hour / 1e9.
A40: VD3 | B40: Fleet cost as share of a top firm's trading revenue | C40: =C39/C38 -> 0.049830716 | D40: VD2 / VD1. A full XTX-scale fleet costs a top market maker single-digit percent of revenue. Research velocity (HRT: 1.6x) is worth far more than that.
B41: Summary: annual compute cost as share of annual value, by use case
...

Sheet Configs
A1: System configurations financial institutions deploy: four reference builds evaluated side by side
A2: One column per configuration. Rows are the specification, the five-year cost, the unit economics and the workload fit. Every cost row reuses the TCO sheet's rates so the four columns are comparable.
A4: Line | B4: Item | C4: Regulated pod | D4: Bank SuperPOD class | E4: Sovereign AI factory | F4: Research factory
B5: Who deploys it | C5: Regional bank, mid-size insurer, exchange | D5: G-SIB or top-100 bank first system (BNY 2024) | E5: G-SIB, payment network, sovereign cloud for banks | F5: Quant trading or market-making firm
B6: Specification
A7: K1 | B7: Nodes or racks | C7: 4 | D7: 64 | E7: 4 | F7: 250
A8: K2 | B8: Unit type (1 = 8-GPU air-cooled node, 2 = GB300 NVL72 liquid-cooled rack) | C8: 1 | D8: 1 | E8: 2 | F8: 1
A9: K3 | B9: GPUs | C9: =C7*8 -> 32 | D9: =D7*8 -> 512 | E9: =E7*72 -> 288 | F9: =F7*8 -> 2000
A10: K4 | B10: GPU memory, TB | C10: =C9*Assumptions!$C$90/1000 -> 5.76 | D10: =D9*Assumptions!$C$90/1000 -> 92.16 | E10: =E9*Assumptions!$C$91/1000 -> 82.944 | F10: =F9*Assumptions!$C$90/1000 -> 360
A11: K5 | B11: FP8 PFLOPS (NVIDIA sparse figures) | C11: =C7*Assumptions!$C$92 -> 288 | D11: =D7*Assumptions!$C$92 -> 4608 | E11: =E7*Assumptions!$C$92*Assumptions!$C$93 -> 2592 | F11: =F7*Assumptions!$C$92 -> 18000
A12: K6 | B12: Scale-up domain, GPUs sharing memory over NVLink | C12: 8 | D12: 8 | E12: 72 | F12: 8
A13: K7 | B13: Scale-out fabric | C13: Top-of-rack Ethernet | D13: InfiniBand (SuperPOD RA) | E13: Spectrum-X or InfiniBand | F13: Spectrum-X Ethernet
A14: K8 | B14: Cooling | C14: Air | D14: Air | E14: Liquid | F14: Air (liquid for Rubin)
A15: K9 | B15: IT power, kW (max) | C15: =C7*Assumptions!$C$74 -> 57.2 | D15: =D7*Assumptions!$C$74 -> 915.2 | E15: =E7*Assumptions!$C$95 -> 540 | F15: =F7*Assumptions!$C$74 -> 3575
A16: K10 | B16: Facility power incl. cooling, kW (average load x PUE) | C16: =C15*Assumptions!$C$75*Assumptions!$C$76 -> 55.77 | D16: =D15*Assumptions!$C$75*Assumptions!$C$76 -> 892.32 | E16: =E15*Assumptions!$C$75*Assumptions!$C$70 -> 465.75 | F16: =F15*Assumptions!$C$75*Assumptions!$C$70 -> 3083.4375
A17: K11 | B17: Where it sits | C17: Bank's own data center or local colo cage | D17: Colo campus in a money-center city | E17: Colo campus in jurisdiction, 10-40 MW contract | F17: Owned or leased DC sited for cheap power
A18: K12 | B18: Software stack | C18: AI Enterprise + NIM blueprints + EDB/Cloudera | D18: AI Enterprise + Base Command + Run:ai | E18: AI Enterprise + NeMo + Nemotron | F18: Own stack (PyTorch, Ray, custom)
B19: Five-year cost, $
A20: K13 | B20: Unit price | C20: =Assumptions!$C$72 -> 420000 | D20: =Assumptions!$C$72 -> 420000 | E20: =Assumptions!$C$94*1000000 -> 3500000 | F20: =Assumptions!$C$96 -> 380000
A21: K14 | B21: Capital incl. networking, storage, installation | C21: =C7*C20*(1+Assumptions!$C$73) -> 2100000 | D21: =D7*D20*(1+Assumptions!$C$73) -> 33600000 | E21: =E7*E20*(1+Assumptions!$C$97) -> 16100000 | F21: =F7*F20*(1+Assumptions!$C$73) -> 118750000
A22: K15 | B22: Electricity per year | C22: =C16*Assumptions!$C$87*Assumptions!$C$77 -> 47730.866 | D22: =D16*Assumptions!$C$87*Assumptions!$C$77 -> 763693.86 | E22: =E16*Assumptions!$C$87*Assumptions!$C$77 -> 398613.07 | F22: =F16*Assumptions!$C$87*Assumptions!$C$77*0.6 -> 1583379.7
A23: K16 | B23: Colocation per year (committed kW x rate; liquid premium for racks; research factory owns its building at ~half the colo rate) | C23: =C15*Assumptions!$C$78*12 -> 140025.6 | D23: =D15*Assumptions!$C$78*12 -> 2240409.6 | E23: =E15*Assumptions!$C$78*(1+Assumptions!$C$98)*12 -> 1586304 | F23: =F15*Assumptions!$C$78*0.5*12 -> 4375800
A24: K17 | B24: Software and support per year (research factory runs its own stack) | C24: =C9*Assumptions!$C$79 -> 144000 | D24: =D9*Assumptions!$C$79 -> 2304000 | E24: =E9*Assumptions!$C$79 -> 1296000 | F24: =F9*Assumptions!$C$79*0.25 -> 2250000
A25: K18 | B25: Operations staff per year | C25: =C7*Assumptions!$C$80 -> 60000 | D25: =D7*Assumptions!$C$80 -> 960000 | E25: =E7*9*Assumptions!$C$80 -> 540000 | F25: =F7*Assumptions!$C$80 -> 3750000
A26: K19 | B26: Operating cost per year | C26: =C22+C23+C24+C25 -> 391756.47 | D26: =D22+D23+D24+D25 -> 6268103.5 | E26: =E22+E23+E24+E25 -> 3820917.1 | F26: =F22+F23+F24+F25 -> 11959180
A27: K20 | B27: Five-year TCO (capital + 5 x operating - 10% residual on units) | C27: =C21+5*C26-C7*C20*Assumptions!$C$88 -> 3890782.3 | D27: =D21+5*D26-D7*D20*Assumptions!$C$88 -> 62252517 | E27: =E21+5*E26-E7*E20*Assumptions!$C$88 -> 33804585 | F27: =F21+5*F26-F7*F20*Assumptions!$C$88 -> 1.690459e+08
A28: K21 | B28: Five-year TCO, $M | C28: =C27/1000000 -> 3.8907823 | D28: =D27/1000000 -> 62.252517 | E28: =E27/1000000 -> 33.804585 | F28: =F27/1000000 -> 169.0459
B29: Unit economics
A30: K22 | B30: Utilisation assumed | C30: 0.4 | D30: =Assumptions!$C$86 -> 0.65 | E30: 0.75 | F30: 0.85
A31: K23 | B31: Used GPU-hours over five years | C31: =C9*Assumptions!$C$87*5*C30 -> 560640 | D31: =D9*Assumptions!$C$87*5*D30 -> 14576640 | E31: =E9*Assumptions!$C$87*5*E30 -> 9460800 | F31: =F9*Assumptions!$C$87*5*F30 -> 74460000
A32: K24 | B32: Effective $ per used GPU-hour | C32: =C27/C31 -> 6.9398943 | D32: =D27/D31 -> 4.2707042 | E32: =E27/E31 -> 3.5731212 | F32: =F27/F31 -> 2.2702914
A33: K25 | B33: Five-year TCO per GPU | C33: =C27/C9 -> 121586.95 | D33: =D27/D9 -> 121586.95 | E33: =E27/E9 -> 117377.03 | F33: =F27/F9 -> 84522.949
A34: K26 | B34: Capital per FP8 PFLOPS | C34: =C21/C11 -> 7291.6667 | D34: =D21/D11 -> 7291.6667 | E34: =E21/E11 -> 6211.4198 | F34: =F21/F11 -> 6597.2222
A35: K27 | B35: Five-year power and facility as share of TCO | C35: =5*(C22+C23)/C27 -> 0.24128369 | D35: =5*(D22+D23)/D27 -> 0.24128369 | E35: =5*(E22+E23)/E27 -> 0.29358696 | F35: =5*(F22+F23)/F27 -> 0.17625922
A36: K28 | B36: Same used hours rented on demand ($6.99) | C36: =C31*Assumptions!$C$82 -> 3918873.6 | D36: =D31*Assumptions!$C$82 -> 1.0189071e+08 | E36: =E31*Assumptions!$C$82 -> 66130992 | F36: =F31*Assumptions!$C$82 -> 520475400
A37: K29 | B37: Owned TCO as share of on-demand rental | C37: =C27/C36 -> 0.9928318 | D37: =D27/D36 -> 0.61097342 | E37: =E27/E36 -> 0.51117614 | F37: =F27/F36 -> 0.32479133
B38: Workload fit (GPUs the configuration can carry, from Workloads)
A39: K30 | B39: Employee assistants of 230,000-user size it can serve | C39: =C9/Workloads!C13 -> 0.083478261 | D39: =D9/Workloads!C13 -> 1.3356522 | E39: =E9/Workloads!C13 -> 0.75130435 | F39: =F9/Workloads!C13 -> 5.2173913
A40: K31 | B40: 10B-parameter transaction-model training runs it can complete per month | C40: =C9/Workloads!C29 -> 0.442368 | D40: =D9/Workloads!C29 -> 7.077888 | E40: =E9/Workloads!C29 -> 3.981312 | F40: =F9/Workloads!C29 -> 27.648
A41: K32 | B41: Share of an XTX-scale research fleet | C41: =C9/Assumptions!$C$67 -> 0.00128 | D41: =D9/Assumptions!$C$67 -> 0.02048 | E41: =E9/Assumptions!$C$67 -> 0.01152 | F41: =F9/Assumptions!$C$67 -> 0.08
...

Sheet Pricing
A1: Pricing: what a financial institution pays per GPU-hour and per million tokens, by route, and where the margin sits
A2: Compares buying routes on one axis ($ per GPU-hour) and then on the unit the business understands (per million tokens).
A4: Line | B4: Item | C4: Value | D4: Formula (in words)
B5: Price per GPU-hour by route (Blackwell B200 class unless noted)
A6: P1 | B6: Own, effective at 65% utilisation (TCO T17) | C6: =TCO!C22 -> 4.2707042 | D6: From TCO.
A7: P2 | B7: Own, at 100% utilisation (TCO T18) | C7: =TCO!C23 -> 2.7759577 | D7: From TCO.
A8: P3 | B8: Cloud reserved | C8: =Assumptions!$C$83 -> 4.75 | D8: $4.75.
A9: P4 | B9: Cloud on-demand | C9: =Assumptions!$C$82 -> 6.99 | D9: $6.99 (range $5.99 to $16.11).
A10: P5 | B10: H100 one-year rental (previous generation) | C10: =Assumptions!$C$85 -> 2.35 | D10: $2.35 (NVIDIA, Mar 2026).
A11: P6 | B11: H100 on-demand median | C11: =Assumptions!$C$84 -> 2.7 | D11: $2.70 (NVIDIA, Jun 2026). Up 35% in eight months: GPU rental prices rose in 2026, which is unusual for a compute market.
A12: P7 | B12: Premium of on-demand cloud over owning (P4 / P1) | C12: =C9/C6 -> 1.6367324 | D12: P4 / P1.
B13: Price per million tokens by route (70B-class open model)
A14: M1 | B14: Tokens one GPU serves per hour | C14: =Assumptions!$C$60*3600 -> 9000000 | D14: 2,500 tokens/s x 3,600.
A15: M2 | B15: Own: $ per million tokens at 65% utilisation | C15: =C6/C14*1000000 -> 0.47452269 | D15: P1 / M1 x 1e6.
A16: M3 | B16: Cloud reserved: $ per million tokens | C16: =C8/C14*1000000 -> 0.52777778 | D16: P3 / M1 x 1e6.
A17: M4 | B17: Cloud on-demand: $ per million tokens | C17: =C9/C14*1000000 -> 0.77666667 | D17: P4 / M1 x 1e6.
A18: M5 | B18: NVIDIA's stated Blackwell floor (GPT-OSS-120B, TensorRT-LLM) | C18: =Assumptions!$C$122 -> 0.02 | D18: $0.02 per million tokens. Our M2 is above it because we assume 65% utilisation, 2,500 tokens/s and a full TCO stack.
A19: M6 | B19: Hosted open-model API | C19: =Assumptions!$C$125 -> 0.6 | D19: $0.60 blended list.
A20: M7 | B20: Frontier API | C20: =Assumptions!$C$124 -> 6 | D20: $6.00 blended list.
A21: M8 | B21: Frontier API premium over owned inference (M7 / M2) | C21: =C20/C15 -> 12.644285 | D21: M7 / M2. This spread is the economic case for banks to run open models on owned GPUs for the bulk of internal traffic, and NVIDIA's open-source pitch (84% of FS respondents say open source matters).
B22: Where the margin sits in the stack
A23: G1 | B23: B200 GPU street price | C23: =Assumptions!$C$126 -> 47500 | D23: $47,500 (Oct 2026).
A24: G2 | B24: NVIDIA gross margin | C24: =Assumptions!$C$28 -> 0.75 | D24: 75.0% GAAP, Q2 FY27.
A25: G3 | B25: Implied NVIDIA cost of goods per GPU | C25: =C23*(1-C24) -> 11875 | D25: G1 x (1 - G2).
A26: G4 | B26: GPU share of the 8-GPU node price | C26: =8*C23/Assumptions!$C$72 -> 0.9047619 | D26: 8 x G1 / node price. The GPUs are most of the box; CPUs, memory and chassis are the remainder.
A27: G5 | B27: GPU share of node capital cost incl. networking and storage | C27: =8*C23/TCO!C8 -> 0.72380952 | D27: 8 x G1 / TCO T3.
A28: G6 | B28: NVIDIA gross profit per 8-GPU node (chips only) | C28: =8*(C23-C25) -> 285000 | D28: 8 x (G1 - G3).
A29: G7 | B29: NVIDIA software (AI Enterprise) over five years per node | C29: =8*Assumptions!$C$79*5 -> 180000 | D29: 8 x $4,500 x 5.
A30: G8 | B30: Software as share of five-year node TCO | C30: =C29/TCO!C17 -> 0.18505276 | D30: G7 / TCO T12. Software is the recurring line NVIDIA can grow in FS without shipping more silicon.
A31: G9 | B31: Cloud provider gross margin on on-demand B200 at 65% utilisation | C31: =1-C6/C9 -> 0.38902658 | D31: 1 - P1 / P4. If the cloud's cost base matches our on-prem TCO.
B32: Financing changes who pays
A33: H1 | B33: Third-party capital NVIDIA's partner platforms target ($B) | C33: =Assumptions!$C$130 -> 500 | D33: $500B (Aug 2026).
A34: H2 | B34: NVIDIA residual-value support, share of an opportunity | C34: =Assumptions!$C$131 -> 0.25 | D34: Up to 25%.
A35: H3 | B35: Five-year node TCO if hardware is financed with 25% residual support instead of 10% ($) | C35: =TCO!C8+TCO!C15*5-TCO!C6*C34 -> 909695.58 | D35: T3 + T10 x 5 - T1 x 25%.
A36: H4 | B36: Saving vs base TCO | C36: =TCO!C17-C35 -> 63000 | D36: T12 - H3.
A37: H5 | B37: Reading | D37: Goldman, Apollo, BlackRock, Blackstone, Brookfield and KKR now finance NVIDIA AI factories. Financial services is NVIDIA's lender as well as its customer. For the FS vertical, the pricing conversation moves from capex to lease rate per GPU-hour, which is the unit banks already use for cloud.

Sheet Sources
A1: Sources
A2: Numbering matches the article at esthercs.dev/research/fs-gpu.
A4: No. | B4: Source | C4: Date | D4: URL
A5: 1 | B5: NVIDIA, Survey Reveals the Financial Services Industry Is Doubling Down on AI Investment and Open Source (State of AI in FS 2026) | C5: 22 Jan 2026 | D5: https://blogs.nvidia.com/blog/ai-in-financial-services-survey-2026/
A6: 2 | B6: Gartner, Forecast: Enterprise IT Spending for the Banking and Investment Services Market, Worldwide, 2023-2029, 4Q25 | C6: 4Q25 | D6: https://www.gartner.com/en/documents/7431362
A7: 3 | B7: Gartner, Worldwide IT Spending to Grow 14.2% in 2026, Totaling $6.37 Trillion | C7: 27 Jul 2026 | D7: https://www.gartner.com/en/newsroom/press-releases/2026-07-27-gartner-forecasts-worldwide-it-spending-to-grow-14-point-2-percent-in-2026-totaling-6-point-37-trillion
A8: 4 | B8: Gartner, Worldwide AI-Optimized IaaS Spending to Grow 96% in 2026 | C8: 10 Aug 2026 | D8: https://www.gartner.com/en/newsroom/press-releases/2026-08-10-gartner-forecasts-worldwide-artificial-intelligence-optimized-iaas-spending-to-grow-96-percent-in-2026
A9: 5 | B9: Gartner, Worldwide AI Spending to Grow 49.5% in 2026 | C9: 16 Sep 2026 | D9: https://www.gartner.com/en/newsroom/press-releases/2026-09-16-gartner-forecasts-worldwide-ai-spending-to-grow-49-point-5-percent-in-2026
A10: 6 | B10: IDC, Worldwide AI and Generative AI Spending, Industry Outlook | C10: 21 Aug 2024 | D10: https://www.idc.com/resource-center/blog/idcs-worldwide-ai-and-generative-ai-spending-industry-outlook/
A11: 7 | B11: Digital Applied, AI Spending Forecasts 2026: Gartner, IDC and Stanford compiled (IDC AI infrastructure figures) | C11: 2026 | D11: https://www.digitalapplied.com/blog/ai-spending-forecasts-2026-gartner-idc-stanford-compiled
A12: 8 | B12: NVIDIA, Financial Results for Second Quarter Fiscal 2027 | C12: Aug 2026 | D12: https://nvidianews.nvidia.com/news/nvidia-announces-financial-results-for-second-quarter-fiscal-2027
A13: 9 | B13: NVIDIA, Financial Results for First Quarter Fiscal 2027 | C13: May 2026 | D13: https://nvidianews.nvidia.com/news/nvidia-announces-financial-results-for-first-quarter-fiscal-2027
A14: 10 | B14: Jensen Huang, NVIDIA AI Factory Compute Is Becoming an Investable Asset Class | C14: 12 Aug 2026 | D14: https://blogs.nvidia.com/blog/nvidia-ai-factory-compute/
A15: 11 | B15: FSB, 2025 List of Global Systemically Important Banks | C15: 27 Nov 2025 | D15: https://www.fsb.org/2025/11/2025-list-of-global-systemically-important-banks-g-sibs/
A16: 12 | B16: S&P Global Market Intelligence, The world's largest banks by assets, 2026 | C16: 29 Apr 2026 | D16: https://www.spglobal.com/market-intelligence/en/news-insights/research/2026/04/the-worlds-largest-banks-by-assets-2026
... A51: 47 | B51: AHEAD, NVIDIA 2026 NPN FSI Partner of the Year | C51: 2026 | D51: https://www.ahead.com/partner/nvidia/
